Workbook

Sheet Summary
A1: NHCX issues: status against my docs
A2: Source: issues.xlsx (Defect register, Error codes ER-1b, DOCS site findings). Each issue checked against site/docs/nhcx/v1 and catalogue/nhcx in this repo, the HANDBOOK text under current/doc, the apps (nhcx-adapter, backend, package, nanoemr) and reports/nhcx-e2e-run-2026-09-21.json. Counts below are formulas over the All issues sheet.
A4: My docs
B5: Total | C5: Blocker | D5: Critical | E5: Major | F5: Minor
A6: Fixed in docs | B6: =COUNTIF('All issues'!$F$5:$F$118,"Fixed in docs") -> 49 | C6: =COUNTIFS('All issues'!$F$5:$F$118,"Fixed in docs",'All issues'!$C$5:$C$118,"Blocker") -> 6 | D6: =COUNTIFS('All issues'!$F$5:$F$118,"Fixed in docs",'All issues'!$C$5:$C$118,"Critical") -> 14 | E6: =COUNTIFS('All issues'!$F$5:$F$118,"Fixed in docs",'All issues'!$C$5:$C$118,"Major") -> 25 | F6: =COUNTIFS('All issues'!$F$5:$F$118,"Fixed in docs",'All issues'!$C$5:$C$118,"Minor") -> 4
A7: Partly fixed | B7: =COUNTIF('All issues'!$F$5:$F$118,"Partly fixed") -> 48 | C7: =COUNTIFS('All issues'!$F$5:$F$118,"Partly fixed",'All issues'!$C$5:$C$118,"Blocker") -> 6 | D7: =COUNTIFS('All issues'!$F$5:$F$118,"Partly fixed",'All issues'!$C$5:$C$118,"Critical") -> 17 | E7: =COUNTIFS('All issues'!$F$5:$F$118,"Partly fixed",'All issues'!$C$5:$C$118,"Major") -> 17 | F7: =COUNTIFS('All issues'!$F$5:$F$118,"Partly fixed",'All issues'!$C$5:$C$118,"Minor") -> 8
A8: Not fixed | B8: =COUNTIF('All issues'!$F$5:$F$118,"Not fixed") -> 7 | C8: =COUNTIFS('All issues'!$F$5:$F$118,"Not fixed",'All issues'!$C$5:$C$118,"Blocker") -> 0 | D8: =COUNTIFS('All issues'!$F$5:$F$118,"Not fixed",'All issues'!$C$5:$C$118,"Critical") -> 2 | E8: =COUNTIFS('All issues'!$F$5:$F$118,"Not fixed",'All issues'!$C$5:$C$118,"Major") -> 2 | F8: =COUNTIFS('All issues'!$F$5:$F$118,"Not fixed",'All issues'!$C$5:$C$118,"Minor") -> 3
A9: Not a docs issue | B9: =COUNTIF('All issues'!$F$5:$F$118,"Not a docs issue") -> 10 | C9: =COUNTIFS('All issues'!$F$5:$F$118,"Not a docs issue",'All issues'!$C$5:$C$118,"Blocker") -> 0 | D9: =COUNTIFS('All issues'!$F$5:$F$118,"Not a docs issue",'All issues'!$C$5:$C$118,"Critical") -> 0 | E9: =COUNTIFS('All issues'!$F$5:$F$118,"Not a docs issue",'All issues'!$C$5:$C$118,"Major") -> 2 | F9: =COUNTIFS('All issues'!$F$5:$F$118,"Not a docs issue",'All issues'!$C$5:$C$118,"Minor") -> 8
A10: Unconfirmed | B10: =COUNTIF('All issues'!$F$5:$F$118,"Unconfirmed") -> 0 | C10: =COUNTIFS('All issues'!$F$5:$F$118,"Unconfirmed",'All issues'!$C$5:$C$118,"Blocker") -> 0 | D10: =COUNTIFS('All issues'!$F$5:$F$118,"Unconfirmed",'All issues'!$C$5:$C$118,"Critical") -> 0 | E10: =COUNTIFS('All issues'!$F$5:$F$118,"Unconfirmed",'All issues'!$C$5:$C$118,"Major") -> 0 | F10: =COUNTIFS('All issues'!$F$5:$F$118,"Unconfirmed",'All issues'!$C$5:$C$118,"Minor") -> 0
A11: Total | B11: =SUM(B6:B10) -> 114 | C11: =SUM(C6:C10) -> 12 | D11: =SUM(D6:D10) -> 33 | E11: =SUM(E6:E10) -> 46 | F11: =SUM(F6:F10) -> 23
A13: Handbook
B14: Total | C14: Blocker | D14: Critical | E14: Major | F14: Minor
A15: Handbook wrong | B15: =COUNTIF('All issues'!$H$5:$H$118,"Handbook wrong") -> 42 | C15: =COUNTIFS('All issues'!$H$5:$H$118,"Handbook wrong",'All issues'!$C$5:$C$118,"Blocker") -> 7 | D15: =COUNTIFS('All issues'!$H$5:$H$118,"Handbook wrong",'All issues'!$C$5:$C$118,"Critical") -> 9 | E15: =COUNTIFS('All issues'!$H$5:$H$118,"Handbook wrong",'All issues'!$C$5:$C$118,"Major") -> 16 | F15: =COUNTIFS('All issues'!$H$5:$H$118,"Handbook wrong",'All issues'!$C$5:$C$118,"Minor") -> 10
A16: Handbook incomplete | B16: =COUNTIF('All issues'!$H$5:$H$118,"Handbook incomplete") -> 36 | C16: =COUNTIFS('All issues'!$H$5:$H$118,"Handbook incomplete",'All issues'!$C$5:$C$118,"Blocker") -> 4 | D16: =COUNTIFS('All issues'!$H$5:$H$118,"Handbook incomplete",'All issues'!$C$5:$C$118,"Critical") -> 13 | E16: =COUNTIFS('All issues'!$H$5:$H$118,"Handbook incomplete",'All issues'!$C$5:$C$118,"Major") -> 15 | F16: =COUNTIFS('All issues'!$H$5:$H$118,"Handbook incomplete",'All issues'!$C$5:$C$118,"Minor") -> 4
A17: Handbook right | B17: =COUNTIF('All issues'!$H$5:$H$118,"Handbook right") -> 6 | C17: =COUNTIFS('All issues'!$H$5:$H$118,"Handbook right",'All issues'!$C$5:$C$118,"Blocker") -> 0 | D17: =COUNTIFS('All issues'!$H$5:$H$118,"Handbook right",'All issues'!$C$5:$C$118,"Critical") -> 1 | E17: =COUNTIFS('All issues'!$H$5:$H$118,"Handbook right",'All issues'!$C$5:$C$118,"Major") -> 3 | F17: =COUNTIFS('All issues'!$H$5:$H$118,"Handbook right",'All issues'!$C$5:$C$118,"Minor") -> 2
A18: Handbook not involved | B18: =COUNTIF('All issues'!$H$5:$H$118,"Handbook not involved") -> 20 | C18: =COUNTIFS('All issues'!$H$5:$H$118,"Handbook not involved",'All issues'!$C$5:$C$118,"Blocker") -> 1 | D18: =COUNTIFS('All issues'!$H$5:$H$118,"Handbook not involved",'All issues'!$C$5:$C$118,"Critical") -> 6 | E18: =COUNTIFS('All issues'!$H$5:$H$118,"Handbook not involved",'All issues'!$C$5:$C$118,"Major") -> 8 | F18: =COUNTIFS('All issues'!$H$5:$H$118,"Handbook not involved",'All issues'!$C$5:$C$118,"Minor") -> 5
A19: Unconfirmed | B19: =COUNTIF('All issues'!$H$5:$H$118,"Unconfirmed") -> 10 | C19: =COUNTIFS('All issues'!$H$5:$H$118,"Unconfirmed",'All issues'!$C$5:$C$118,"Blocker") -> 0 | D19: =COUNTIFS('All issues'!$H$5:$H$118,"Unconfirmed",'All issues'!$C$5:$C$118,"Critical") -> 4 | E19: =COUNTIFS('All issues'!$H$5:$H$118,"Unconfirmed",'All issues'!$C$5:$C$118,"Major") -> 4 | F19: =COUNTIFS('All issues'!$H$5:$H$118,"Unconfirmed",'All issues'!$C$5:$C$118,"Minor") -> 2
A20: Total | B20: =SUM(B15:B19) -> 114 | C20: =SUM(C15:C19) -> 12 | D20: =SUM(D15:D19) -> 33 | E20: =SUM(E15:E19) -> 46 | F20: =SUM(F15:F19) -> 23
A22: Since last check
B23: Total | C23: Blocker | D23: Critical | E23: Major | F23: Minor
A24: Newly fixed | B24: =COUNTIF('All issues'!$N$5:$N$118,"Newly fixed") -> 0 | C24: =COUNTIFS('All issues'!$N$5:$N$118,"Newly fixed",'All issues'!$C$5:$C$118,"Blocker") -> 0 | D24: =COUNTIFS('All issues'!$N$5:$N$118,"Newly fixed",'All issues'!$C$5:$C$118,"Critical") -> 0 | E24: =COUNTIFS('All issues'!$N$5:$N$118,"Newly fixed",'All issues'!$C$5:$C$118,"Major") -> 0 | F24: =COUNTIFS('All issues'!$N$5:$N$118,"Newly fixed",'All issues'!$C$5:$C$118,"Minor") -> 0
A25: Newly partly fixed | B25: =COUNTIF('All issues'!$N$5:$N$118,"Newly partly fixed") -> 1 | C25: =COUNTIFS('All issues'!$N$5:$N$118,"Newly partly fixed",'All issues'!$C$5:$C$118,"Blocker") -> 0 | D25: =COUNTIFS('All issues'!$N$5:$N$118,"Newly partly fixed",'All issues'!$C$5:$C$118,"Critical") -> 1 | E25: =COUNTIFS('All issues'!$N$5:$N$118,"Newly partly fixed",'All issues'!$C$5:$C$118,"Major") -> 0 | F25: =COUNTIFS('All issues'!$N$5:$N$118,"Newly partly fixed",'All issues'!$C$5:$C$118,"Minor") -> 0
A26: Still fixed | B26: =COUNTIF('All issues'!$N$5:$N$118,"Still fixed") -> 57 | C26: =COUNTIFS('All issues'!$N$5:$N$118,"Still fixed",'All issues'!$C$5:$C$118,"Blocker") -> 6 | D26: =COUNTIFS('All issues'!$N$5:$N$118,"Still fixed",'All issues'!$C$5:$C$118,"Critical") -> 14 | E26: =COUNTIFS('All issues'!$N$5:$N$118,"Still fixed",'All issues'!$C$5:$C$118,"Major") -> 27 | F26: =COUNTIFS('All issues'!$N$5:$N$118,"Still fixed",'All issues'!$C$5:$C$118,"Minor") -> 10
A27: Still partly fixed | B27: =COUNTIF('All issues'!$N$5:$N$118,"Still partly fixed") -> 43 | C27: =COUNTIFS('All issues'!$N$5:$N$118,"Still partly fixed",'All issues'!$C$5:$C$118,"Blocker") -> 5 | D27: =COUNTIFS('All issues'!$N$5:$N$118,"Still partly fixed",'All issues'!$C$5:$C$118,"Critical") -> 16 | E27: =COUNTIFS('All issues'!$N$5:$N$118,"Still partly fixed",'All issues'!$C$5:$C$118,"Major") -> 17 | F27: =COUNTIFS('All issues'!$N$5:$N$118,"Still partly fixed",'All issues'!$C$5:$C$118,"Minor") -> 5
A28: Still open | B28: =COUNTIF('All issues'!$N$5:$N$118,"Still open") -> 10 | C28: =COUNTIFS('All issues'!$N$5:$N$118,"Still open",'All issues'!$C$5:$C$118,"Blocker") -> 1 | D28: =COUNTIFS('All issues'!$N$5:$N$118,"Still open",'All issues'!$C$5:$C$118,"Critical") -> 2 | E28: =COUNTIFS('All issues'!$N$5:$N$118,"Still open",'All issues'!$C$5:$C$118,"Major") -> 2 | F28: =COUNTIFS('All issues'!$N$5:$N$118,"Still open",'All issues'!$C$5:$C$118,"Minor") -> 5
A29: Re-assessed | B29: =COUNTIF('All issues'!$N$5:$N$118,"Re-assessed") -> 1 | C29: =COUNTIFS('All issues'!$N$5:$N$118,"Re-assessed",'All issues'!$C$5:$C$118,"Blocker") -> 0 | D29: =COUNTIFS('All issues'!$N$5:$N$118,"Re-assessed",'All issues'!$C$5:$C$118,"Critical") -> 0 | E29: =COUNTIFS('All issues'!$N$5:$N$118,"Re-assessed",'All issues'!$C$5:$C$118,"Major") -> 0 | F29: =COUNTIFS('All issues'!$N$5:$N$118,"Re-assessed",'All issues'!$C$5:$C$118,"Minor") -> 1
A30: Regressed | B30: =COUNTIF('All issues'!$N$5:$N$118,"Regressed") -> 2 | C30: =COUNTIFS('All issues'!$N$5:$N$118,"Regressed",'All issues'!$C$5:$C$118,"Blocker") -> 0 | D30: =COUNTIFS('All issues'!$N$5:$N$118,"Regressed",'All issues'!$C$5:$C$118,"Critical") -> 0 | E30: =COUNTIFS('All issues'!$N$5:$N$118,"Regressed",'All issues'!$C$5:$C$118,"Major") -> 0 | F30: =COUNTIFS('All issues'!$N$5:$N$118,"Regressed",'All issues'!$C$5:$C$118,"Minor") -> 2
A31: Total | B31: =SUM(B24:B30) -> 114 | C31: =SUM(C24:C30) -> 12 | D31: =SUM(D24:D30) -> 33 | E31: =SUM(E24:E30) -> 46 | F31: =SUM(F24:F30) -> 23
A33: Confirmed by the live sandbox run | B33: =COUNTIF('All issues'!$K$5:$K$118,"Yes") -> 63
A34: Needs NHA (platform or spec owner) | B34: =COUNTIF('All issues'!$M$5:$M$118,"*Needs NHA*") -> 42
A35: Issues checked | B35: =COUNTA('All issues'!$A$5:$A$118) -> 114

Sheet All issues
A1: All issues
A2: Every issue in issues.xlsx, checked against the docs in this repo, the apps (nhcx-adapter, backend, package, nanoemr) and the live sandbox run of 21 Sep 2026.
A4: ID | B4: From sheet | C4: Severity | D4: API / Area | E4: Finding (from issues.xlsx) | F4: My docs: status | G4: My docs: evidence | H4: Handbook: verdict | I4: Handbook: evidence | J4: What the apps and live run actually do | K4: Confirmed live | L4: Left to fix | M4: Bucket | N4: Since last check | O4: What changed
A5: 2.1 | B5: Defect register | C5: Blocker | D5: Base URLs | E5: Base URLs irreconcilable across sources; production hosts are different domains. | F5: Partly fixed | G5: getting-started/base-urls.md:27-32 and reference/environments-and-addresses.md:21-28 give sandbox and production bases; production exchange apisprod.nha.gov.in/hcx, participant apisprod.nha.gov.in/pmjay/hcx/participanthcxservice, ABDM proxy, portal, face auth added. base-urls.md:56 and environments:54-58 call the host swap an inference and say to check onboarding letter. | H5: Handbook wrong | I5: Handbook 3.2 and Quick Reference give sandbox https://apisbx.abdm.gov.in/pmjay/sbxhcx and production https://apis.abdm.gov.in/pmjay/hcx. Section 2.3 posts /preauth/submit to that host. That host is not the exchange. | J5: Sandbox: nhcx-adapter/internal/config/config.go:56-58 uses apisbx.abdm.gov.in/hcx/v1, .../participanthcxservice and dev.abdm.gov.in v3 sessions. Production defaults at config.go:50-52 are apis.abdm.gov.in/hcx/v1, apis.abdm.gov.in/pmjay/hcx/participanthcxservice and live.abdm.gov.in. These are a host swap the code infers. | K5: Yes | L5: Sandbox done. Production still contradicts the apps (apis.abdm.gov.in) and now the new skills: plugins/nhcx/skills/nhcx-full/gateway/G2-configuration.md:22-23, G4-registry.md:24, G5-protocol-headers.md:33 (same in coverage, claim) say apis.abdm.gov.in. Reconcile and label production rows unverified in the tables. | M5: Wrong in handbook, Left to fix | N5: Still partly fixed | O5: nhcx-registry.yaml no longer has apis.abdm.gov.in/pmjay/hcx (server now apisprod at :48) and an inference caveat was added, but the new NHCX skills publish the opposite production host.
A6: 2.2 | B6: Defect register | C6: Blocker | D6: Session | E6: Session token endpoint differs three ways across two API versions. | F6: Fixed in docs | G6: getting-started/session-token.md:17-38 documents POST dev.abdm.gov.in/api/hiecm/gateway/v3/sessions with REQUEST-ID, TIMESTAMP, X-CM-ID and JSON grantType; :73-84 'The other call named session' contrasts it with participant /get/session. api/registry/index.md:16 repeats the warning. | H6: Handbook wrong | I6: Handbook 3.1 has POST /get/session on Host apisbx.abdm.gov.in, form-encoded grant_type. That form and body belong to the participant service call, but the host lacks /pmjay/sbxhcx/participanthcxservice. The call exists, so 'cannot obtain a token' overstates the problem: only the host is wrong. | J6: nhcx-adapter/internal/abdm/client.go:209-231 supports both modes. The default 'sessions' sends JSON grantType plus REQUEST-ID, TIMESTAMP and X-CM-ID. 'get-session' posts a form to Participant+/get/session (config.go:402). backend/nhcx-adapter/config.json sets auth.mode sessions. | K6: Yes | L6: None for the v3 sessions call (issued the live token, e2e UC-04). Optional: say the participant /get/session call has not been run live. | M6: Fixed in my docs, Wrong in handbook | N6: Still fixed | O6: No change, except api/registry/index.md:16 now also warns the two session calls differ.
A7: 2.3 | B7: Defect register | C7: Blocker | D7: Envelope headers | E7: Three x-hcx-* obligations are inverted between sources. | F7: Partly fixed | G7: getting-started/jwe-message-format.md:95,97 and reference/envelope-fields.md:32,34 make request_id and workflow_id Optional. x-hcx-ben-abha-id is still Mandatory 'on every exchange' at jwe-message-format.md:100, envelope-fields.md:37,65, authentication.md:40,58,91,110,127,145,161,178,220, status-and-search.md:46. | H7: Handbook incomplete | I7: Handbook 2.1 table: request_id Yes, workflow_id Yes, ben-abha-id Optional. Optional matches live behaviour for ben-abha-id. Always sending request_id is harmless. workflow_id Yes is too strict. | J7: nhcx-adapter/internal/nhcx/headers.go:151 always generates request_id. headers.go:156-158 drops an empty workflow_id; backend/provider/internal/api/coverage.go:296 sets it only sometimes. No Go app ever sets x-hcx-ben-abha-id; it appears only in the Bruno samples (package/apis/*.bru:22). | K7: Yes | L7: 168 live messages without x-hcx-ben-abha-id, 0 refusals. Change Mandatory to optional or conditional (PMJAY only, unconfirmed) at the lines cited. The new skills (nhcx-full/gateway/G5-protocol-headers.md) also never set it, so docs and skills disagree. | M7: Wrong in handbook, Left to fix | N7: Still open | O7: No change to the ben-abha-id obligation; authentication.md now repeats Mandatory in nine tables.
A8: 2.3b | B8: Defect register | C8: Critical | D8: Envelope headers | E8: HANDBOOK omits five envelope fields DOCS documents. | F8: Fixed in docs | G8: getting-started/jwe-message-format.md:101-104 (use_case, error_details mandatory on a protocol response, debug_details, debug_flag), :113-122 domain headers; reference/envelope-fields.md:38-41 and :164-180. | H8: Handbook incomplete | I8: Handbook 2.1 field table (lines 182-193) stops at x-hcx-ben-abha-id. None of the five fields appears. | J8: nhcx-adapter/internal/nhcx/headers.go:130-160 never sets use_case, error_details or debug fields. adapter.go:449 accepts an inbound ProtocolResponse or /v1/error notice without a JWE. No app emits x-hcx-error_details. | K8: No | L8: None. Minor: debug_flag values disagree (jwe-message-format.md:104 'Send INFO', envelope-fields.md:41 'Error, Info or Debug'). error_details not run live (no fault injected). | M8: Fixed in my docs, Wrong in handbook | N8: Still fixed | O8: Now also covered on the new jwe-message-format.md page; a small debug_flag casing inconsistency appeared between the two pages.
A9: 2.4 | B9: Defect register | C9: Critical | D9: Protocol status | E9: HANDBOOK's x-hcx-status vocabulary matches neither the current nor the superseded set. | F9: Fixed in docs | G9: getting-started/jwe-message-format.md:155-188 'Status values' lists the seven canonical values with a worked preauth sequence and marks the Open Protocol set superseded; reference/envelope-fields.md:122-145 'Status words' matches. | H9: Handbook wrong | I9: Handbook Appendix C.2 lists request.initiated, request.acknowledged, request.queried, request.complete, request.error, request.rejected. Only request.initiated overlaps. Its own D5 has NHCX-1011 for an invalid x-hcx-status. | J9: nhcx-adapter/internal/nhcx/headers.go:86-91 defaults to request.initiated or response.complete. adapter.go:755 returns receipt protocol_status request.queued. The e2e run sent response.partial then response.complete on task/on_submit. | K9: Yes | L9: None. Optional: cite e2e finding 2, where a second decision on a completed thread was refused with 400. | M9: Fixed in my docs, Wrong in handbook | N9: Still fixed | O9: No change beyond the new page restating the same set.
A10: 2.5 | B10: Defect register | C10: Critical | D10: Correlation ID | E10: HANDBOOK states half the correlation rule and omits the retirement rule. | F10: Partly fixed | G10: getting-started/jwe-message-format.md:134-141 and reference/envelope-fields.md:67-93: a request sets correlation_id to its own api_call_id, a response echoes it, api_call_id differs on a response, a failed ID is retired (NHCX-1006). | H10: Handbook incomplete | I10: Handbook 2.1 says correlation_id 'must remain the same across the full lifecycle'. There is no retirement or inequality rule, yet its own D5 lists NHCX-1006 'Request with same correlation id already exist'. | J10: nhcx-adapter/internal/nhcx/headers.go:150-152 gives correlation_id and api_call_id independent random UUIDs, so requests are not seeded from api_call_id. adapter.go:192-205 copies the request's correlation onto a response. | K10: Yes | L10: Reword 'Request: this message's own api_call_id' to 'may' at jwe-message-format.md:136 and envelope-fields.md:76; keep echo, inequality and retirement rules. New skill nhcx-full/gateway/G5-protocol-headers.md:86 uses a fresh UUID, matching the apps. | M10: Wrong in handbook, Left to fix | N10: Still partly fixed | O10: No change; the seeding rule is now also on the new jwe-message-format.md page.
A11: 2.6 | B11: Defect register | C11: Major | D11: Timestamps | E11: HANDBOOK over-generalises the IST rule. | F11: Partly fixed | G11: getting-started/session-token.md:35,100,204 require gateway TIMESTAMP in UTC with milliseconds and Z; :101 x-hcx-timestamp as +05:30 without milliseconds. jwe-message-format.md:143-153 and envelope-fields.md:147-161 give +05:30, epoch on input, PAYR-1005 24h bound. | H11: Handbook wrong | I11: Handbook 1.3 and Quick Reference: 'All timestamps must be in IST timezone (+05:30). UTC or other zones will cause validation failures.' 3.1 never mentions the sessions TIMESTAMP. | J11: nhcx-adapter/internal/abdm/client.go:229 sends TIMESTAMP as time.RFC3339 UTC with no milliseconds. nhcx/headers.go:28-31 sends x-hcx-timestamp as a colon-less host-local offset (+0530); the Alpine image sets no TZ, so it may be +0000 (unconfirmed). | K11: Yes | L11: Soften the milliseconds requirement at session-token.md:35,100,204 (no-millis TIMESTAMP issued a live token). Note in jwe-message-format.md:145 that colon-less +0530 was accepted live. The new skills (nhcx-full/gateway/G3-session-token.md:62, G5-protocol-headers.md:51) already describe the app behaviour. | M11: Wrong in handbook, Left to fix | N11: Still partly fixed | O11: No change to the rule; the new skills now document the no-millis and +0530 forms, which the site pages still contradict.
A12: 2.7 | B12: Defect register | C12: Major | D12: Auth header | E12: Auth header name is not agreed. | F12: Fixed in docs | G12: getting-started/session-token.md:54 and reference/environments-and-addresses.md:74-77 say to send bearer_auth and Authorization with the same value and explain why; environments:65-72 table gives the header per service. | H12: Handbook incomplete | I12: Handbook 2.3 and 3.3 show only 'bearer_auth: Bearer <token>'. | J12: nhcx-adapter/internal/abdm/client.go:548-549 sets bearer_auth (raw map key, not canonicalised) and Authorization: Bearer on every registry and gateway call. | K12: Yes | L12: None. The live run proves that sending both works, not which header each service reads. | M12: Fixed in my docs, Wrong in handbook | N12: Still fixed | O12: No change.
A13: 2.8 | B13: Defect register | C13: Minor | D13: Session | E13: Token lifetime stated as fact when it is contested. | F13: Partly fixed | G13: getting-started/session-token.md:62-68 names 300/1200/6000, relies on none, refreshes on age and retries once on 401. Fixed 1200s/20 min remains: nhcx-registry.yaml:65,84,88,104,133,147 (feeds api/registry/index.md:24, registry-get-session.mdx:5) and roles/provider/pmjay-adjudication-apis.md:46. | H13: Handbook wrong | I13: Handbook 3.1: 'Tokens expire after 1200 seconds (20 minutes)', with sample expires_in 1200. | J13: nhcx-adapter/internal/abdm/client.go:258-262 reads expiresIn/expires_in from the response and falls back to auth.tokenTtlSeconds (1200 in backend/nhcx-adapter/config.json). client.go:541-560 refetches the token once on 401. | K13: No | L13: Drop the fixed lifetime in nhcx-registry.yaml:65,84,88,104 and pmjay-adjudication-apis.md:46. Add to session-token.md:66 'read expiresIn from the response', as the adapter and nhcx-full/gateway/G3-session-token.md:35 do. | M13: Wrong in handbook, Left to fix | N13: Still partly fixed | O13: The rewritten get/session prose added two more fixed '20 minutes' claims (Postconditions :84, Common mistakes :88); nothing was removed.
A14: 2.9 | B14: Defect register | C14: Major | D14: ABHA format | E14: HANDBOOK mandates two ABHA formats without saying which applies where. DOCS resolves it. | F14: Partly fixed | G14: jwe-message-format.md:108 now notes the published header sample sends 14 digits but NHCX-1018 asks for XX-XXXX-XXXX-XXXX, and says format at header build. building-and-sending-a-jwe.md:44-47 says hyphenate only after NHCX-1018. envelope-fields.md:37 and troubleshooting.md:46 still say the gateway wants hyphens. | H14: Unconfirmed | I14: Handbook 2.1 table: ben-abha-id 'no hyphens allowed'. Quick Reference: 'ABHA without hyphens'. D5 NHCX-1018 demands XX-XXXX-XXXX-XXXX. There is no scope, and no run has shown which one the header needs. | J14: No Go app sends x-hcx-ben-abha-id (grep of backend/, nhcx-adapter/). package/apis/03-preauth/v1-preauth-on-submit.bru:22 sends 91711234567890 with no hyphens. The bundle builders use unhyphenated ABHA. | K14: No | L14: Make jwe-message-format.md:108, envelope-fields.md:37 and troubleshooting.md:46 say what building-and-sending-a-jwe.md:47 says (hyphenate only if NHCX-1018 is returned), and state the header format has not been observed live. | M14: Left to fix | N14: Still partly fixed | O14: jwe-message-format.md:108 now acknowledges the unhyphenated sample, closer to building-and-sending-a-jwe.md, but still not the same rule.
A15: 3.0.1 | B15: Defect register | C15: Major | D15: Paths | E15: The /v1 prefix appears and disappears within HANDBOOK. | F15: Fixed in docs | G15: Every use-case path in catalogue/openapi/nhcx/v1/*.yaml is under /v1; provider-checklist.md:28,30,33 use /v1. Unprefixed paths remain only in roles/provider/provider-checklist.md:187-191 (quoted NHA test cases TC-PA/TC-CL). | H15: Handbook wrong | I15: Confirmed: 2.3 POST /preauth/submit, 8.6 /task/submit, 6.5 /insuranceplan/on_request, 12.1 /communication/request and /communication/on_request, but 2.5 /v1/preauth/on_submit and 10.2 /v1/task/submit. | J15: nhcx-adapter/internal/nhcx/headers.go TargetURL joins base .../hcx/v1 with v1/... paths. All 168 live messages went to v1/* operations (e2e report section 3). | K15: Yes | L15: Optional: annotate provider-checklist.md:187-191 to say the real paths are /v1/preauth/submit, /v1/claim/submit and /v1/task/submit. | M15: Fixed in my docs, Wrong in handbook | N15: Still fixed | O15: No change.
... A118: DX-14 | B118: DOCS site findings | C118: Minor | D118: Unresolved in the spec, surfaced by DOCS | E118: x-hcx-debug_flag is typed two ways, and the session token has three published lifetimes. | F118: Partly fixed | G118: envelope-fields.md:55-61 and jwe-message-format.md:104 say send INFO, but envelope-fields.md:41 row and x-hcx-debug_flag in the specs (nhcx-claim.yaml:605-611) still say Error, Info or Debug. getting-started/session-token.md:64 cites 300/1200/6000, rely on none; no mention of reading expiresIn. | H118: Unconfirmed | I118: Handbook 1200s figure not checked; handbook not located. | J118: Adapter sends no debug_flag. Token: reads expiresIn from the response (nhcx-adapter/internal/abdm/client.go:260), defaults to 1200s when absent (internal/config/config.go:343). Lifetime not recorded in the e2e run. | K118: No | L118: Align envelope-fields.md:41 and x-hcx-debug_flag in catalogue/openapi/nhcx/v1/*.yaml with 'send INFO'. session-token.md:64: say read expiresIn (line 45 of the sample) from the response. Settling both is Spec owner / NHA. | M118: Left to fix, Needs NHA | N118: Still partly fixed | O118: The new JWE message format page says send INFO, but the reference row and the specs were not aligned.

Sheet Fixed in my docs
A1: Fixed in my docs
A2: Issues the docs in this repo already get right.
A4: ID | B4: From sheet | C4: Severity | D4: API / Area | E4: Finding (from issues.xlsx) | F4: My docs: status | G4: My docs: evidence | H4: Handbook: verdict | I4: Handbook: evidence | J4: What the apps and live run actually do | K4: Confirmed live | L4: Left to fix | M4: Bucket | N4: Since last check | O4: What changed
A5: 2.2 | B5: Defect register | C5: Blocker | D5: Session | E5: Session token endpoint differs three ways across two API versions. | F5: Fixed in docs | G5: getting-started/session-token.md:17-38 documents POST dev.abdm.gov.in/api/hiecm/gateway/v3/sessions with REQUEST-ID, TIMESTAMP, X-CM-ID and JSON grantType; :73-84 'The other call named session' contrasts it with participant /get/session. api/registry/index.md:16 repeats the warning. | H5: Handbook wrong | I5: Handbook 3.1 has POST /get/session on Host apisbx.abdm.gov.in, form-encoded grant_type. That form and body belong to the participant service call, but the host lacks /pmjay/sbxhcx/participanthcxservice. The call exists, so 'cannot obtain a token' overstates the problem: only the host is wrong. | J5: nhcx-adapter/internal/abdm/client.go:209-231 supports both modes. The default 'sessions' sends JSON grantType plus REQUEST-ID, TIMESTAMP and X-CM-ID. 'get-session' posts a form to Participant+/get/session (config.go:402). backend/nhcx-adapter/config.json sets auth.mode sessions. | K5: Yes | L5: None for the v3 sessions call (issued the live token, e2e UC-04). Optional: say the participant /get/session call has not been run live. | M5: Fixed in my docs, Wrong in handbook | N5: Still fixed | O5: No change, except api/registry/index.md:16 now also warns the two session calls differ.
A6: 2.3b | B6: Defect register | C6: Critical | D6: Envelope headers | E6: HANDBOOK omits five envelope fields DOCS documents. | F6: Fixed in docs | G6: getting-started/jwe-message-format.md:101-104 (use_case, error_details mandatory on a protocol response, debug_details, debug_flag), :113-122 domain headers; reference/envelope-fields.md:38-41 and :164-180. | H6: Handbook incomplete | I6: Handbook 2.1 field table (lines 182-193) stops at x-hcx-ben-abha-id. None of the five fields appears. | J6: nhcx-adapter/internal/nhcx/headers.go:130-160 never sets use_case, error_details or debug fields. adapter.go:449 accepts an inbound ProtocolResponse or /v1/error notice without a JWE. No app emits x-hcx-error_details. | K6: No | L6: None. Minor: debug_flag values disagree (jwe-message-format.md:104 'Send INFO', envelope-fields.md:41 'Error, Info or Debug'). error_details not run live (no fault injected). | M6: Fixed in my docs, Wrong in handbook | N6: Still fixed | O6: Now also covered on the new jwe-message-format.md page; a small debug_flag casing inconsistency appeared between the two pages.
A7: 2.4 | B7: Defect register | C7: Critical | D7: Protocol status | E7: HANDBOOK's x-hcx-status vocabulary matches neither the current nor the superseded set. | F7: Fixed in docs | G7: getting-started/jwe-message-format.md:155-188 'Status values' lists the seven canonical values with a worked preauth sequence and marks the Open Protocol set superseded; reference/envelope-fields.md:122-145 'Status words' matches. | H7: Handbook wrong | I7: Handbook Appendix C.2 lists request.initiated, request.acknowledged, request.queried, request.complete, request.error, request.rejected. Only request.initiated overlaps. Its own D5 has NHCX-1011 for an invalid x-hcx-status. | J7: nhcx-adapter/internal/nhcx/headers.go:86-91 defaults to request.initiated or response.complete. adapter.go:755 returns receipt protocol_status request.queued. The e2e run sent response.partial then response.complete on task/on_submit. | K7: Yes | L7: None. Optional: cite e2e finding 2, where a second decision on a completed thread was refused with 400. | M7: Fixed in my docs, Wrong in handbook | N7: Still fixed | O7: No change beyond the new page restating the same set.
A8: 2.7 | B8: Defect register | C8: Major | D8: Auth header | E8: Auth header name is not agreed. | F8: Fixed in docs | G8: getting-started/session-token.md:54 and reference/environments-and-addresses.md:74-77 say to send bearer_auth and Authorization with the same value and explain why; environments:65-72 table gives the header per service. | H8: Handbook incomplete | I8: Handbook 2.3 and 3.3 show only 'bearer_auth: Bearer <token>'. | J8: nhcx-adapter/internal/abdm/client.go:548-549 sets bearer_auth (raw map key, not canonicalised) and Authorization: Bearer on every registry and gateway call. | K8: Yes | L8: None. The live run proves that sending both works, not which header each service reads. | M8: Fixed in my docs, Wrong in handbook | N8: Still fixed | O8: No change.
A9: 3.0.1 | B9: Defect register | C9: Major | D9: Paths | E9: The /v1 prefix appears and disappears within HANDBOOK. | F9: Fixed in docs | G9: Every use-case path in catalogue/openapi/nhcx/v1/*.yaml is under /v1; provider-checklist.md:28,30,33 use /v1. Unprefixed paths remain only in roles/provider/provider-checklist.md:187-191 (quoted NHA test cases TC-PA/TC-CL). | H9: Handbook wrong | I9: Confirmed: 2.3 POST /preauth/submit, 8.6 /task/submit, 6.5 /insuranceplan/on_request, 12.1 /communication/request and /communication/on_request, but 2.5 /v1/preauth/on_submit and 10.2 /v1/task/submit. | J9: nhcx-adapter/internal/nhcx/headers.go TargetURL joins base .../hcx/v1 with v1/... paths. All 168 live messages went to v1/* operations (e2e report section 3). | K9: Yes | L9: Optional: annotate provider-checklist.md:187-191 to say the real paths are /v1/preauth/submit, /v1/claim/submit and /v1/task/submit. | M9: Fixed in my docs, Wrong in handbook | N9: Still fixed | O9: No change.
A10: IP-3 | B10: Defect register | C10: Major | D10: Insurance plan | E10: Mandatory input type with an optional value. | F10: Fixed in docs | G10: reference/fhir/insurance-plan-request.md:33-36 pair each input type with a valueString; data elements l.114-115 give the value itself 1..1. No 0..1 value row. | H10: Handbook wrong | I10: Handbook l.575-576: input[0].type 1..1, input[0].valueString 0..1. | J10: plan.go:43-53 adds an input only when its value is non-empty, so a type never travels without a valueString. | K10: Yes | L10: None | M10: Fixed in my docs, Wrong in handbook | N10: Still fixed | O10: No change.
A11: IP-6 | B11: Defect register | C11: Minor | D11: Insurance plan | E11: Description truncated mid-sentence. | F11: Fixed in docs | G11: reference/fhir/insurance-plan-response-package-based.md:100 'MaximumImplantsAllowed | 1, 0 | Cap on the number of implants'; roles/provider/pmjay-provider.md:65 complete too. | H11: Handbook wrong | I11: Handbook l.648: max_implants_allowed '...in one transaction cycle including the' ends mid-sentence. | J11: No app evidence | K11: No | L11: None | M11: Fixed in my docs, Wrong in handbook | N11: Still fixed | O11: No change.
A12: CE-1 | B12: Defect register | C12: Critical | D12: Coverage eligibility | E12: An invalid FHIR purpose code is published. | F12: Fixed in docs | G12: reference/fhir/coverage-eligibility-request.md:132 lists discovery, validation, benefits, auth-requirements; l.212 binds http://hl7.org/fhir/eligibilityrequest-purpose. No AUTH_REQUIREMENT in site/docs/nhcx, catalogue/nhcx, catalogue/openapi/nhcx or plugins/nhcx. | H12: Handbook wrong | I12: Handbook 7.4 (l.694) says 'the AUTH_REQUIREMENT purpose'; 7.3 (l.683) lists discovery, validation, benefits, auth-requirements; 7.5 (l.715) lists three. | J12: backend/provider/internal/api/coverage.go:177-186 sends discovery and auth-requirements; package/fhir/B1/auth-requirements.json purpose auth-requirements. | K12: Yes | L12: None | M12: Fixed in my docs, Wrong in handbook | N12: Still fixed | O12: No change.
A13: CE-4 | B13: Defect register | C13: Major | D13: Coverage eligibility | E13: A non-existent FHIR data type is published. | F13: Fixed in docs | G13: reference/fhir/coverage-eligibility-request.md:50 shows item[].quantity as 'value 1'; no 'numeric' type for quantity in reference/fhir/. | H13: Handbook wrong | I13: Handbook 7.5 l.733: item[*].quantity.value typed 'numeric'. | J13: backend/provider/internal/nhcx/coverage.go:237-243 sends quantity {value: n}, a SimpleQuantity. | K13: Yes | L13: None | M13: Fixed in my docs, Wrong in handbook | N13: Still fixed | O13: No change.
A14: CE-5 | B14: Defect register | C14: Major | D14: Coverage eligibility | E14: Purpose values asymmetric between request and response. | F14: Fixed in docs | G14: reference/fhir/coverage-eligibility-response.md:36,104,182 show purpose auth-requirements; l.141,145 cover authorizationSupporting for auth-requirements. | H14: Handbook wrong | I14: Handbook 7.6 l.741 response purpose 'validation OR benefits'; request l.715 allows auth-requirements. | J14: Payer echoes whatever was asked: backend/payer/internal/fhir/eligibility.go:156-162,234. package/fhir/C3/C3-response-pmjay.json purpose auth-requirements. | K14: Yes | L14: None | M14: Fixed in my docs, Wrong in handbook | N14: Still fixed | O14: No change.
A15: CE-8 | B15: Defect register | C15: Major | D15: Coverage eligibility | E15: An undocumented dependency chain is load-bearing. | F15: Fixed in docs | G15: getting-started/finding-participants-and-policies.md:103, roles/provider/registration-and-eligibility.md:46,80, catalogue/nhcx/decisions/eligibility-purpose.md:71,76 and catalogue/nhcx/concepts/coverage-eligibility-purposes.md:88 state lookup, then discovery, then validation. | H15: Handbook incomplete | I15: Chain stated only in 7.4 Discovery row (l.692). | J15: backend/provider/internal/api/coverage.go:25,177 falls back to discovery; the e2e run sent discovery, validation, auth-requirements in that order. | K15: Yes | L15: registration-and-eligibility.md:84 still says discovery 'appears in no published sample' (package/fhir/B1/discovery.json and the live run contradict it); drop it. l.46 still cites 'the handbook' in the third person. | M15: Fixed in my docs, Wrong in handbook | N15: Still fixed | O15: No change.
... A53: DX-13 | B53: DOCS site findings | C53: Major | D53: Unresolved in the spec, surfaced by DOCS | E53: Both portal spec pages print the domain-header prefix wrongly. | F53: Fixed in docs | G53: reference/envelope-fields.md:176-180 (domain headers) and :205-209 'The header prefix' say both pages print x-NHCX- and to send x-hcx-. | H53: Handbook not involved | I53: Not applicable | J53: nhcx-adapter/internal/nhcx/headers.go:16-23 uses x-hcx- for every protected header; backend provider/payer likewise. 168 messages accepted in the e2e run. | K53: Yes | L53: Spec owner / NHA. | M53: Fixed in my docs, Needs NHA | N53: Still fixed | O53: No change.

Sheet Wrong in handbook
A1: Wrong in handbook
A2: Where the NHCX Integration Handbook V1.0 is wrong or leaves out what an integrator needs.
A4: ID | B4: From sheet | C4: Severity | D4: API / Area | E4: Finding (from issues.xlsx) | F4: My docs: status | G4: My docs: evidence | H4: Handbook: verdict | I4: Handbook: evidence | J4: What the apps and live run actually do | K4: Confirmed live | L4: Left to fix | M4: Bucket | N4: Since last check | O4: What changed
A5: 2.1 | B5: Defect register | C5: Blocker | D5: Base URLs | E5: Base URLs irreconcilable across sources; production hosts are different domains. | F5: Partly fixed | G5: getting-started/base-urls.md:27-32 and reference/environments-and-addresses.md:21-28 give sandbox and production bases; production exchange apisprod.nha.gov.in/hcx, participant apisprod.nha.gov.in/pmjay/hcx/participanthcxservice, ABDM proxy, portal, face auth added. base-urls.md:56 and environments:54-58 call the host swap an inference and say to check onboarding letter. | H5: Handbook wrong | I5: Handbook 3.2 and Quick Reference give sandbox https://apisbx.abdm.gov.in/pmjay/sbxhcx and production https://apis.abdm.gov.in/pmjay/hcx. Section 2.3 posts /preauth/submit to that host. That host is not the exchange. | J5: Sandbox: nhcx-adapter/internal/config/config.go:56-58 uses apisbx.abdm.gov.in/hcx/v1, .../participanthcxservice and dev.abdm.gov.in v3 sessions. Production defaults at config.go:50-52 are apis.abdm.gov.in/hcx/v1, apis.abdm.gov.in/pmjay/hcx/participanthcxservice and live.abdm.gov.in. These are a host swap the code infers. | K5: Yes | L5: Sandbox done. Production still contradicts the apps (apis.abdm.gov.in) and now the new skills: plugins/nhcx/skills/nhcx-full/gateway/G2-configuration.md:22-23, G4-registry.md:24, G5-protocol-headers.md:33 (same in coverage, claim) say apis.abdm.gov.in. Reconcile and label production rows unverified in the tables. | M5: Wrong in handbook, Left to fix | N5: Still partly fixed | O5: nhcx-registry.yaml no longer has apis.abdm.gov.in/pmjay/hcx (server now apisprod at :48) and an inference caveat was added, but the new NHCX skills publish the opposite production host.
A6: 2.2 | B6: Defect register | C6: Blocker | D6: Session | E6: Session token endpoint differs three ways across two API versions. | F6: Fixed in docs | G6: getting-started/session-token.md:17-38 documents POST dev.abdm.gov.in/api/hiecm/gateway/v3/sessions with REQUEST-ID, TIMESTAMP, X-CM-ID and JSON grantType; :73-84 'The other call named session' contrasts it with participant /get/session. api/registry/index.md:16 repeats the warning. | H6: Handbook wrong | I6: Handbook 3.1 has POST /get/session on Host apisbx.abdm.gov.in, form-encoded grant_type. That form and body belong to the participant service call, but the host lacks /pmjay/sbxhcx/participanthcxservice. The call exists, so 'cannot obtain a token' overstates the problem: only the host is wrong. | J6: nhcx-adapter/internal/abdm/client.go:209-231 supports both modes. The default 'sessions' sends JSON grantType plus REQUEST-ID, TIMESTAMP and X-CM-ID. 'get-session' posts a form to Participant+/get/session (config.go:402). backend/nhcx-adapter/config.json sets auth.mode sessions. | K6: Yes | L6: None for the v3 sessions call (issued the live token, e2e UC-04). Optional: say the participant /get/session call has not been run live. | M6: Fixed in my docs, Wrong in handbook | N6: Still fixed | O6: No change, except api/registry/index.md:16 now also warns the two session calls differ.
A7: 2.3 | B7: Defect register | C7: Blocker | D7: Envelope headers | E7: Three x-hcx-* obligations are inverted between sources. | F7: Partly fixed | G7: getting-started/jwe-message-format.md:95,97 and reference/envelope-fields.md:32,34 make request_id and workflow_id Optional. x-hcx-ben-abha-id is still Mandatory 'on every exchange' at jwe-message-format.md:100, envelope-fields.md:37,65, authentication.md:40,58,91,110,127,145,161,178,220, status-and-search.md:46. | H7: Handbook incomplete | I7: Handbook 2.1 table: request_id Yes, workflow_id Yes, ben-abha-id Optional. Optional matches live behaviour for ben-abha-id. Always sending request_id is harmless. workflow_id Yes is too strict. | J7: nhcx-adapter/internal/nhcx/headers.go:151 always generates request_id. headers.go:156-158 drops an empty workflow_id; backend/provider/internal/api/coverage.go:296 sets it only sometimes. No Go app ever sets x-hcx-ben-abha-id; it appears only in the Bruno samples (package/apis/*.bru:22). | K7: Yes | L7: 168 live messages without x-hcx-ben-abha-id, 0 refusals. Change Mandatory to optional or conditional (PMJAY only, unconfirmed) at the lines cited. The new skills (nhcx-full/gateway/G5-protocol-headers.md) also never set it, so docs and skills disagree. | M7: Wrong in handbook, Left to fix | N7: Still open | O7: No change to the ben-abha-id obligation; authentication.md now repeats Mandatory in nine tables.
A8: 2.3b | B8: Defect register | C8: Critical | D8: Envelope headers | E8: HANDBOOK omits five envelope fields DOCS documents. | F8: Fixed in docs | G8: getting-started/jwe-message-format.md:101-104 (use_case, error_details mandatory on a protocol response, debug_details, debug_flag), :113-122 domain headers; reference/envelope-fields.md:38-41 and :164-180. | H8: Handbook incomplete | I8: Handbook 2.1 field table (lines 182-193) stops at x-hcx-ben-abha-id. None of the five fields appears. | J8: nhcx-adapter/internal/nhcx/headers.go:130-160 never sets use_case, error_details or debug fields. adapter.go:449 accepts an inbound ProtocolResponse or /v1/error notice without a JWE. No app emits x-hcx-error_details. | K8: No | L8: None. Minor: debug_flag values disagree (jwe-message-format.md:104 'Send INFO', envelope-fields.md:41 'Error, Info or Debug'). error_details not run live (no fault injected). | M8: Fixed in my docs, Wrong in handbook | N8: Still fixed | O8: Now also covered on the new jwe-message-format.md page; a small debug_flag casing inconsistency appeared between the two pages.
A9: 2.4 | B9: Defect register | C9: Critical | D9: Protocol status | E9: HANDBOOK's x-hcx-status vocabulary matches neither the current nor the superseded set. | F9: Fixed in docs | G9: getting-started/jwe-message-format.md:155-188 'Status values' lists the seven canonical values with a worked preauth sequence and marks the Open Protocol set superseded; reference/envelope-fields.md:122-145 'Status words' matches. | H9: Handbook wrong | I9: Handbook Appendix C.2 lists request.initiated, request.acknowledged, request.queried, request.complete, request.error, request.rejected. Only request.initiated overlaps. Its own D5 has NHCX-1011 for an invalid x-hcx-status. | J9: nhcx-adapter/internal/nhcx/headers.go:86-91 defaults to request.initiated or response.complete. adapter.go:755 returns receipt protocol_status request.queued. The e2e run sent response.partial then response.complete on task/on_submit. | K9: Yes | L9: None. Optional: cite e2e finding 2, where a second decision on a completed thread was refused with 400. | M9: Fixed in my docs, Wrong in handbook | N9: Still fixed | O9: No change beyond the new page restating the same set.
A10: 2.5 | B10: Defect register | C10: Critical | D10: Correlation ID | E10: HANDBOOK states half the correlation rule and omits the retirement rule. | F10: Partly fixed | G10: getting-started/jwe-message-format.md:134-141 and reference/envelope-fields.md:67-93: a request sets correlation_id to its own api_call_id, a response echoes it, api_call_id differs on a response, a failed ID is retired (NHCX-1006). | H10: Handbook incomplete | I10: Handbook 2.1 says correlation_id 'must remain the same across the full lifecycle'. There is no retirement or inequality rule, yet its own D5 lists NHCX-1006 'Request with same correlation id already exist'. | J10: nhcx-adapter/internal/nhcx/headers.go:150-152 gives correlation_id and api_call_id independent random UUIDs, so requests are not seeded from api_call_id. adapter.go:192-205 copies the request's correlation onto a response. | K10: Yes | L10: Reword 'Request: this message's own api_call_id' to 'may' at jwe-message-format.md:136 and envelope-fields.md:76; keep echo, inequality and retirement rules. New skill nhcx-full/gateway/G5-protocol-headers.md:86 uses a fresh UUID, matching the apps. | M10: Wrong in handbook, Left to fix | N10: Still partly fixed | O10: No change; the seeding rule is now also on the new jwe-message-format.md page.
A11: 2.6 | B11: Defect register | C11: Major | D11: Timestamps | E11: HANDBOOK over-generalises the IST rule. | F11: Partly fixed | G11: getting-started/session-token.md:35,100,204 require gateway TIMESTAMP in UTC with milliseconds and Z; :101 x-hcx-timestamp as +05:30 without milliseconds. jwe-message-format.md:143-153 and envelope-fields.md:147-161 give +05:30, epoch on input, PAYR-1005 24h bound. | H11: Handbook wrong | I11: Handbook 1.3 and Quick Reference: 'All timestamps must be in IST timezone (+05:30). UTC or other zones will cause validation failures.' 3.1 never mentions the sessions TIMESTAMP. | J11: nhcx-adapter/internal/abdm/client.go:229 sends TIMESTAMP as time.RFC3339 UTC with no milliseconds. nhcx/headers.go:28-31 sends x-hcx-timestamp as a colon-less host-local offset (+0530); the Alpine image sets no TZ, so it may be +0000 (unconfirmed). | K11: Yes | L11: Soften the milliseconds requirement at session-token.md:35,100,204 (no-millis TIMESTAMP issued a live token). Note in jwe-message-format.md:145 that colon-less +0530 was accepted live. The new skills (nhcx-full/gateway/G3-session-token.md:62, G5-protocol-headers.md:51) already describe the app behaviour. | M11: Wrong in handbook, Left to fix | N11: Still partly fixed | O11: No change to the rule; the new skills now document the no-millis and +0530 forms, which the site pages still contradict.
A12: 2.7 | B12: Defect register | C12: Major | D12: Auth header | E12: Auth header name is not agreed. | F12: Fixed in docs | G12: getting-started/session-token.md:54 and reference/environments-and-addresses.md:74-77 say to send bearer_auth and Authorization with the same value and explain why; environments:65-72 table gives the header per service. | H12: Handbook incomplete | I12: Handbook 2.3 and 3.3 show only 'bearer_auth: Bearer <token>'. | J12: nhcx-adapter/internal/abdm/client.go:548-549 sets bearer_auth (raw map key, not canonicalised) and Authorization: Bearer on every registry and gateway call. | K12: Yes | L12: None. The live run proves that sending both works, not which header each service reads. | M12: Fixed in my docs, Wrong in handbook | N12: Still fixed | O12: No change.
A13: 2.8 | B13: Defect register | C13: Minor | D13: Session | E13: Token lifetime stated as fact when it is contested. | F13: Partly fixed | G13: getting-started/session-token.md:62-68 names 300/1200/6000, relies on none, refreshes on age and retries once on 401. Fixed 1200s/20 min remains: nhcx-registry.yaml:65,84,88,104,133,147 (feeds api/registry/index.md:24, registry-get-session.mdx:5) and roles/provider/pmjay-adjudication-apis.md:46. | H13: Handbook wrong | I13: Handbook 3.1: 'Tokens expire after 1200 seconds (20 minutes)', with sample expires_in 1200. | J13: nhcx-adapter/internal/abdm/client.go:258-262 reads expiresIn/expires_in from the response and falls back to auth.tokenTtlSeconds (1200 in backend/nhcx-adapter/config.json). client.go:541-560 refetches the token once on 401. | K13: No | L13: Drop the fixed lifetime in nhcx-registry.yaml:65,84,88,104 and pmjay-adjudication-apis.md:46. Add to session-token.md:66 'read expiresIn from the response', as the adapter and nhcx-full/gateway/G3-session-token.md:35 do. | M13: Wrong in handbook, Left to fix | N13: Still partly fixed | O13: The rewritten get/session prose added two more fixed '20 minutes' claims (Postconditions :84, Common mistakes :88); nothing was removed.
A14: 3.0.1 | B14: Defect register | C14: Major | D14: Paths | E14: The /v1 prefix appears and disappears within HANDBOOK. | F14: Fixed in docs | G14: Every use-case path in catalogue/openapi/nhcx/v1/*.yaml is under /v1; provider-checklist.md:28,30,33 use /v1. Unprefixed paths remain only in roles/provider/provider-checklist.md:187-191 (quoted NHA test cases TC-PA/TC-CL). | H14: Handbook wrong | I14: Confirmed: 2.3 POST /preauth/submit, 8.6 /task/submit, 6.5 /insuranceplan/on_request, 12.1 /communication/request and /communication/on_request, but 2.5 /v1/preauth/on_submit and 10.2 /v1/task/submit. | J14: nhcx-adapter/internal/nhcx/headers.go TargetURL joins base .../hcx/v1 with v1/... paths. All 168 live messages went to v1/* operations (e2e report section 3). | K14: Yes | L14: Optional: annotate provider-checklist.md:187-191 to say the real paths are /v1/preauth/submit, /v1/claim/submit and /v1/task/submit. | M14: Fixed in my docs, Wrong in handbook | N14: Still fixed | O14: No change.
A15: IP-1 | B15: Defect register | C15: Critical | D15: Insurance plan | E15: Four different code systems for Task.code across one document. | F15: Partly fixed | G15: catalogue/openapi/nhcx/v1/nhcx-insurance-plan.yaml:67,327 no longer name a Task.code system (old URI gone). reference/fhir/insurance-plan-request.md:42 still correct. Old URI remains at catalogue/nhcx/concepts/insurance-plan.md:89, and in stale gitignored build output site/static/specs/nhcx-insurance-plan.yaml:75. | H15: Handbook wrong | I15: Handbook line 574 (6.4) uses https://nhcx.abdm.gov.in/api; 8.6 (l.1015), 10.4 (l.1646), 11.6 (l.1918), 12.x (l.1994) use financialtaskcode; 11.5 (l.1851) uses ndhm-task-codes. Only 6.4 is wrong. | J15: poll in financialtaskcode: backend/provider/internal/nhcx/plan.go:60, package/fhir/B2/B2-request.json. deliver in ndhm-task-codes: backend/payer/internal/fhir/paymentreconciliation.go:25,187. approve in hl7 task-code: backend/payer/internal/fhir/wire.go:28. | K15: Yes | L15: Change catalogue/nhcx/concepts/insurance-plan.md:89 to system http://terminology.hl7.org/CodeSystem/financialtaskcode. Rebuild site/static/specs so the stale copy is replaced. The spec half of the earlier fix is done. | M15: Wrong in handbook, Left to fix | N15: Still partly fixed | O15: The OpenAPI spec no longer carries the old URI; the catalogue concept atom still does.
... A82: ER-11 | B82: Defect register | C82: Minor | D82: Error codes | E82: Appendix qualifier misapplies to half its content. | F82: Partly fixed | G82: error-code-guide.md:24-29 separates the gateway from the PMJAY payer. But the new Error codes tab page is titled 'PMJAY error codes' (pmjay-error-codes.mdx:2-3,15) and lists the 19 NHCX- gateway codes under it; only its intro line 17 says NHCX- codes come from the exchange. | H82: Handbook wrong | I82: Handbook.md:2222 has 'Appendix D: Error Codes (currently implemented in PMJAY)' over D5 NHCX- gateway codes (2432-2454), which are exchange-level. | J82: No app evidence | K82: No | L82: Docs: retitle reference/pmjay-error-codes.mdx to something like 'Error codes' or 'NHCX and PMJAY error codes'. Handbook title: Spec owner / NHA. | M82: Wrong in handbook, Left to fix, Needs NHA | N82: Regressed | O82: The docs had avoided the handbook's PMJAY title; the new error page reuses it over gateway codes.

Sheet Left to fix
A1: Left to fix
A2: Still wrong or incomplete in the docs in this repo. The Left to fix column says what to change.
A4: ID | B4: From sheet | C4: Severity | D4: API / Area | E4: Finding (from issues.xlsx) | F4: My docs: status | G4: My docs: evidence | H4: Handbook: verdict | I4: Handbook: evidence | J4: What the apps and live run actually do | K4: Confirmed live | L4: Left to fix | M4: Bucket | N4: Since last check | O4: What changed
A5: 2.1 | B5: Defect register | C5: Blocker | D5: Base URLs | E5: Base URLs irreconcilable across sources; production hosts are different domains. | F5: Partly fixed | G5: getting-started/base-urls.md:27-32 and reference/environments-and-addresses.md:21-28 give sandbox and production bases; production exchange apisprod.nha.gov.in/hcx, participant apisprod.nha.gov.in/pmjay/hcx/participanthcxservice, ABDM proxy, portal, face auth added. base-urls.md:56 and environments:54-58 call the host swap an inference and say to check onboarding letter. | H5: Handbook wrong | I5: Handbook 3.2 and Quick Reference give sandbox https://apisbx.abdm.gov.in/pmjay/sbxhcx and production https://apis.abdm.gov.in/pmjay/hcx. Section 2.3 posts /preauth/submit to that host. That host is not the exchange. | J5: Sandbox: nhcx-adapter/internal/config/config.go:56-58 uses apisbx.abdm.gov.in/hcx/v1, .../participanthcxservice and dev.abdm.gov.in v3 sessions. Production defaults at config.go:50-52 are apis.abdm.gov.in/hcx/v1, apis.abdm.gov.in/pmjay/hcx/participanthcxservice and live.abdm.gov.in. These are a host swap the code infers. | K5: Yes | L5: Sandbox done. Production still contradicts the apps (apis.abdm.gov.in) and now the new skills: plugins/nhcx/skills/nhcx-full/gateway/G2-configuration.md:22-23, G4-registry.md:24, G5-protocol-headers.md:33 (same in coverage, claim) say apis.abdm.gov.in. Reconcile and label production rows unverified in the tables. | M5: Wrong in handbook, Left to fix | N5: Still partly fixed | O5: nhcx-registry.yaml no longer has apis.abdm.gov.in/pmjay/hcx (server now apisprod at :48) and an inference caveat was added, but the new NHCX skills publish the opposite production host.
A6: 2.3 | B6: Defect register | C6: Blocker | D6: Envelope headers | E6: Three x-hcx-* obligations are inverted between sources. | F6: Partly fixed | G6: getting-started/jwe-message-format.md:95,97 and reference/envelope-fields.md:32,34 make request_id and workflow_id Optional. x-hcx-ben-abha-id is still Mandatory 'on every exchange' at jwe-message-format.md:100, envelope-fields.md:37,65, authentication.md:40,58,91,110,127,145,161,178,220, status-and-search.md:46. | H6: Handbook incomplete | I6: Handbook 2.1 table: request_id Yes, workflow_id Yes, ben-abha-id Optional. Optional matches live behaviour for ben-abha-id. Always sending request_id is harmless. workflow_id Yes is too strict. | J6: nhcx-adapter/internal/nhcx/headers.go:151 always generates request_id. headers.go:156-158 drops an empty workflow_id; backend/provider/internal/api/coverage.go:296 sets it only sometimes. No Go app ever sets x-hcx-ben-abha-id; it appears only in the Bruno samples (package/apis/*.bru:22). | K6: Yes | L6: 168 live messages without x-hcx-ben-abha-id, 0 refusals. Change Mandatory to optional or conditional (PMJAY only, unconfirmed) at the lines cited. The new skills (nhcx-full/gateway/G5-protocol-headers.md) also never set it, so docs and skills disagree. | M6: Wrong in handbook, Left to fix | N6: Still open | O6: No change to the ben-abha-id obligation; authentication.md now repeats Mandatory in nine tables.
A7: 2.5 | B7: Defect register | C7: Critical | D7: Correlation ID | E7: HANDBOOK states half the correlation rule and omits the retirement rule. | F7: Partly fixed | G7: getting-started/jwe-message-format.md:134-141 and reference/envelope-fields.md:67-93: a request sets correlation_id to its own api_call_id, a response echoes it, api_call_id differs on a response, a failed ID is retired (NHCX-1006). | H7: Handbook incomplete | I7: Handbook 2.1 says correlation_id 'must remain the same across the full lifecycle'. There is no retirement or inequality rule, yet its own D5 lists NHCX-1006 'Request with same correlation id already exist'. | J7: nhcx-adapter/internal/nhcx/headers.go:150-152 gives correlation_id and api_call_id independent random UUIDs, so requests are not seeded from api_call_id. adapter.go:192-205 copies the request's correlation onto a response. | K7: Yes | L7: Reword 'Request: this message's own api_call_id' to 'may' at jwe-message-format.md:136 and envelope-fields.md:76; keep echo, inequality and retirement rules. New skill nhcx-full/gateway/G5-protocol-headers.md:86 uses a fresh UUID, matching the apps. | M7: Wrong in handbook, Left to fix | N7: Still partly fixed | O7: No change; the seeding rule is now also on the new jwe-message-format.md page.
A8: 2.6 | B8: Defect register | C8: Major | D8: Timestamps | E8: HANDBOOK over-generalises the IST rule. | F8: Partly fixed | G8: getting-started/session-token.md:35,100,204 require gateway TIMESTAMP in UTC with milliseconds and Z; :101 x-hcx-timestamp as +05:30 without milliseconds. jwe-message-format.md:143-153 and envelope-fields.md:147-161 give +05:30, epoch on input, PAYR-1005 24h bound. | H8: Handbook wrong | I8: Handbook 1.3 and Quick Reference: 'All timestamps must be in IST timezone (+05:30). UTC or other zones will cause validation failures.' 3.1 never mentions the sessions TIMESTAMP. | J8: nhcx-adapter/internal/abdm/client.go:229 sends TIMESTAMP as time.RFC3339 UTC with no milliseconds. nhcx/headers.go:28-31 sends x-hcx-timestamp as a colon-less host-local offset (+0530); the Alpine image sets no TZ, so it may be +0000 (unconfirmed). | K8: Yes | L8: Soften the milliseconds requirement at session-token.md:35,100,204 (no-millis TIMESTAMP issued a live token). Note in jwe-message-format.md:145 that colon-less +0530 was accepted live. The new skills (nhcx-full/gateway/G3-session-token.md:62, G5-protocol-headers.md:51) already describe the app behaviour. | M8: Wrong in handbook, Left to fix | N8: Still partly fixed | O8: No change to the rule; the new skills now document the no-millis and +0530 forms, which the site pages still contradict.
A9: 2.8 | B9: Defect register | C9: Minor | D9: Session | E9: Token lifetime stated as fact when it is contested. | F9: Partly fixed | G9: getting-started/session-token.md:62-68 names 300/1200/6000, relies on none, refreshes on age and retries once on 401. Fixed 1200s/20 min remains: nhcx-registry.yaml:65,84,88,104,133,147 (feeds api/registry/index.md:24, registry-get-session.mdx:5) and roles/provider/pmjay-adjudication-apis.md:46. | H9: Handbook wrong | I9: Handbook 3.1: 'Tokens expire after 1200 seconds (20 minutes)', with sample expires_in 1200. | J9: nhcx-adapter/internal/abdm/client.go:258-262 reads expiresIn/expires_in from the response and falls back to auth.tokenTtlSeconds (1200 in backend/nhcx-adapter/config.json). client.go:541-560 refetches the token once on 401. | K9: No | L9: Drop the fixed lifetime in nhcx-registry.yaml:65,84,88,104 and pmjay-adjudication-apis.md:46. Add to session-token.md:66 'read expiresIn from the response', as the adapter and nhcx-full/gateway/G3-session-token.md:35 do. | M9: Wrong in handbook, Left to fix | N9: Still partly fixed | O9: The rewritten get/session prose added two more fixed '20 minutes' claims (Postconditions :84, Common mistakes :88); nothing was removed.
A10: 2.9 | B10: Defect register | C10: Major | D10: ABHA format | E10: HANDBOOK mandates two ABHA formats without saying which applies where. DOCS resolves it. | F10: Partly fixed | G10: jwe-message-format.md:108 now notes the published header sample sends 14 digits but NHCX-1018 asks for XX-XXXX-XXXX-XXXX, and says format at header build. building-and-sending-a-jwe.md:44-47 says hyphenate only after NHCX-1018. envelope-fields.md:37 and troubleshooting.md:46 still say the gateway wants hyphens. | H10: Unconfirmed | I10: Handbook 2.1 table: ben-abha-id 'no hyphens allowed'. Quick Reference: 'ABHA without hyphens'. D5 NHCX-1018 demands XX-XXXX-XXXX-XXXX. There is no scope, and no run has shown which one the header needs. | J10: No Go app sends x-hcx-ben-abha-id (grep of backend/, nhcx-adapter/). package/apis/03-preauth/v1-preauth-on-submit.bru:22 sends 91711234567890 with no hyphens. The bundle builders use unhyphenated ABHA. | K10: No | L10: Make jwe-message-format.md:108, envelope-fields.md:37 and troubleshooting.md:46 say what building-and-sending-a-jwe.md:47 says (hyphenate only if NHCX-1018 is returned), and state the header format has not been observed live. | M10: Left to fix | N10: Still partly fixed | O10: jwe-message-format.md:108 now acknowledges the unhyphenated sample, closer to building-and-sending-a-jwe.md, but still not the same rule.
